#Expyriment 0.9.0 (Python 3.6.6), .xpe-file, coding: ISO8859-1
#date: Tue Aug 14 2018 09:53:42
#sha1: None
#modules: 
#display: size=(800, 600), window_mode=True, open_gl=2
#os: uname_result(system='Linux', node='L3460', release='4.4.0-109-generic', version='#132~14.04.1-Ubuntu SMP Tue Jan 9 21:46:42 UTC 2018', machine='x86_64', processor='x86_64')
Time,Type,Event,Value,Detail,Detail2
284,stdout,received,'LEVEL 1'
4290,stdout,received,'        Trial:   None\n\n        Stimuli: [9]\n        '
5619,design,log,
#design: #exp: Arithmatic test
#design: block_cnt,block_id,block_LEVEL,trial_cnt,trial_id
#design: 0,0,LEVEL 1,0,0
#design: 0,0,LEVEL 1,1,1
#design: 0,0,LEVEL 1,2,2
#design: 0,0,LEVEL 1,3,3
#design: 0,0,LEVEL 1,4,4
5619,design,logged,
5619,Experiment,started
6620,Stimulus,presented,1
7621,Stimulus,presented,1
8622,Stimulus,presented,3
9623,Stimulus,presented,3
10624,Stimulus,presented,5
11625,Stimulus,presented,5
12626,Stimulus,presented,7
13627,Stimulus,presented,7
14628,Stimulus,presented,9
15629,Stimulus,presented,9
15630,stdout,received,'LEVEL 2'
19635,stdout,received,'        Trial:   None\n\n        Stimuli: [18]\n        '
19636,stderr,received,'Traceback (most recent call last):'
19636,stderr,received,'  File "arithmatictask_v0.py", line 49, in <module>'
19636,stderr,received,'    control.start()'
19636,stderr,received,'  File "/home/k/workbench/cognitionExp/lib/python3.6/site-packages/expyriment/control/_experiment_control.py", line 73, in start'
19636,stderr,received,'    raise Exception("Experiment is already started!")'
19636,stderr,received,'Exception: Experiment is already started!'
