#Expyriment 0.9.0 (Python 3.6.6), .xpe-file, coding: ISO8859-1
#date: Tue Aug 14 2018 14:58:09
#sha1: None
#modules: 
#display: size=(800, 600), window_mode=True, open_gl=2
#os: uname_result(system='Linux', node='L3460', release='4.4.0-109-generic', version='#132~14.04.1-Ubuntu SMP Tue Jan 9 21:46:42 UTC 2018', machine='x86_64', processor='x86_64')
Time,Type,Event,Value,Detail,Detail2
294,stdout,received,'LEVEL 1'
4299,stdout,received,'        Trial:   None\n\n        Stimuli: [9]\n        '
5312,design,log,
#design: #exp: Arithmatic test
#design: block_cnt,block_id,block_LEVEL,trial_cnt,trial_id
#design: 0,0,LEVEL 1,0,0
#design: 0,0,LEVEL 1,1,1
#design: 0,0,LEVEL 1,2,2
#design: 0,0,LEVEL 1,3,3
#design: 0,0,LEVEL 1,4,4
5313,design,logged,
5313,Experiment,started
6314,stdout,received,"<class 'expyriment.stimuli._textline.TextLine'>"
7314,stdout,received,"<class 'expyriment.stimuli._textline.TextLine'>"
8314,stdout,received,"<class 'expyriment.stimuli._textline.TextLine'>"
9314,stdout,received,"<class 'expyriment.stimuli._textline.TextLine'>"
10314,stdout,received,"<class 'expyriment.stimuli._textline.TextLine'>"
10314,stdout,received,'LEVEL 2'
14319,stdout,received,'        Trial:   None\n\n        Stimuli: [18]\n        '
14320,stderr,received,'Traceback (most recent call last):'
14320,stderr,received,'  File "arithmatictask_v0.py", line 49, in <module>'
14320,stderr,received,'    control.start()'
14320,stderr,received,'  File "/home/k/workbench/cognitionExp/lib/python3.6/site-packages/expyriment/control/_experiment_control.py", line 73, in start'
14320,stderr,received,'    raise Exception("Experiment is already started!")'
14320,stderr,received,'Exception: Experiment is already started!'
