#Expyriment 0.9.0 (Python 3.6.6), .xpe-file, coding: ISO8859-1
#date: Tue Aug 14 2018 15:07:23
#sha1: None
#modules: 
#display: size=(800, 600), window_mode=True, open_gl=2
#os: uname_result(system='Linux', node='L3460', release='4.4.0-109-generic', version='#132~14.04.1-Ubuntu SMP Tue Jan 9 21:46:42 UTC 2018', machine='x86_64', processor='x86_64')
Time,Type,Event,Value,Detail,Detail2
272,stdout,received,'LEVEL 1'
5905,design,log,
#design: #exp: Arithmatic test
#design: block_cnt,block_id,block_LEVEL,trial_cnt,trial_id
#design: 0,0,LEVEL 1,0,0
#design: 0,0,LEVEL 1,1,1
#design: 0,0,LEVEL 1,2,2
#design: 0,0,LEVEL 1,3,3
#design: 0,0,LEVEL 1,4,4
5905,design,logged,
5905,Experiment,started
6906,stdout,received,"<class 'expyriment.stimuli._textline.TextLine'>"
7906,stdout,received,"<class 'expyriment.stimuli._textline.TextLine'>"
8906,stdout,received,"<class 'expyriment.stimuli._textline.TextLine'>"
9906,stdout,received,"<class 'expyriment.stimuli._textline.TextLine'>"
10906,stderr,received,'Traceback (most recent call last):'
10906,stderr,received,'  File "arithmatictask_v0.py", line 56, in <module>'
10906,stderr,received,'    print(type(t.stimuli[1]))'
10906,stderr,received,'IndexError: list index out of range'
